#VRML_SIM R2025a utf8

EXTERNPROTO "https://raw.githubusercontent.com/cyberbotics/webots/R2025a/projects/objects/backgrounds/protos/TexturedBackgroundLight.proto"

WorldInfo {
  basicTimeStep 16
  contactProperties [
    ContactProperties {
      material1 "Aluminum alloy"
      material2 "Aluminum Oxide"
      coulombFriction [
        0.3
      ]
      softERP 0
    }
  ]
}
Viewpoint {
  orientation 0 0 1 1.5707963267948966
  position 0.6563038260677558 -0.7268648226256976 0.6259240123394949
}
Background {
  skyColor [
    0.494118 0.6 0.717647
  ]
}
TexturedBackgroundLight {
  castShadows FALSE
}
Solid {
  children [
    Shape {
      appearance PBRAppearance {
        baseColorMap ImageTexture {
          url [
            "https://raw.githubusercontent.com/cyberbotics/webots/R2025a/projects/appearances/protos/textures/parquetry/chequered_parquetry_base_color.jpg"
          ]
        }
        roughness 1
        roughnessMap ImageTexture {
          url [
            "https://raw.githubusercontent.com/cyberbotics/webots/R2025a/projects/appearances/protos/textures/parquetry/chequered_parquetry_roughness.jpg"
          ]
        }
        metalness 0
        normalMap ImageTexture {
          url [
            "https://raw.githubusercontent.com/cyberbotics/webots/R2025a/projects/appearances/protos/textures/parquetry/chequered_parquetry_normal.jpg"
          ]
        }
        occlusionMap ImageTexture {
          url [
            "https://raw.githubusercontent.com/cyberbotics/webots/R2025a/projects/appearances/protos/textures/parquetry/chequered_parquetry_occlusion.jpg"
          ]
        }
      }
      geometry IndexedFaceSet {
        coord Coordinate {
          point [
            -5 -5 0
            5 -5 0
            -5 5 0
            5 5 0
          ]
        }
        texCoord TextureCoordinate {
          point [
            0 0
            20 0
            0 20
            20 20
          ]
        }
        coordIndex [
          2, 0, 1, 3, -1
        ]
        texCoordIndex [
          2, 0, 1, 3, -1
        ]
      }
    }
  ]
  name "floor"
  model "floor"
  boundingObject Plane {
    size 10 10
  }
  locked TRUE
}
Robot {
  children [
    DEF LRMate200iD Robot {
      translation -0.005634474731243159 -1.3150507249856669e-05 -0.015602533870308454
      rotation 0.332500623389323 -0.9314187471732832 -0.14799477308291342 0.0031895022073676242
      children [
        Shape {
          appearance DEF Base_material PBRAppearance {
            baseColor 0.529412 0.54902 0.54902
            roughness 1
            metalness 0
          }
          geometry DEF base Mesh {
            url [
              "../protos/LRMate-200iD/meshes/Base.stl"
            ]
          }
        }
        HingeJoint {
          jointParameters HingeJointParameters {
            position -6.8684121383336225e-06
            axis 0 0 1
            anchor 0 0 0.042741
          }
          device [
            DEF J1 RotationalMotor {
              name "J1"
              minPosition -2.9671
              maxPosition 2.9671
              maxTorque 10000
            }
            PositionSensor {
              name "J1_sensor"
            }
          ]
          endPoint DEF J1 Solid {
            translation 0 0 0.042741
            rotation 0 0 -1 6.868384714326857e-06
            children [
              Shape {
                appearance DEF J1_material PBRAppearance {
                  baseColor 0.976471 0.85098 0.14902
                  roughness 1
                  metalness 0
                }
                geometry DEF j1 Mesh {
                  url [
                    "../protos/LRMate-200iD/meshes/J1.stl"
                  ]
                }
              }
              HingeJoint {
                jointParameters HingeJointParameters {
                  position -6.071503843076848e-06
                  axis 0 -1 0
                  anchor 0.05 0 0.28726
                }
                device [
                  RotationalMotor {
                    name "J2"
                    minPosition -2.5307
                    maxPosition 1.7453
                    maxTorque 10000
                  }
                  PositionSensor {
                    name "J2_sensor"
                  }
                ]
                endPoint DEF J2 Solid {
                  translation 0.05 0 0.28726
                  rotation 0 0.9999999999999999 0 6.071487225652567e-06
                  children [
                    Shape {
                      appearance DEF J2_material PBRAppearance {
                        baseColor 0.976471 0.85098 0.14902
                        roughness 1
                        metalness 0
                      }
                      geometry DEF j2 Mesh {
                        url [
                          "../protos/LRMate-200iD/meshes/J2.stl"
                        ]
                      }
                    }
                    HingeJoint {
                      jointParameters HingeJointParameters {
                        position -6.763097311113023e-06
                        axis 0 -1 0
                        anchor 0 0 0.33
                      }
                      device [
                        RotationalMotor {
                          name "J3"
                          minPosition -1.2217
                          maxPosition 3.5779
                          maxTorque 10000
                        }
                        PositionSensor {
                          name "J3_sensor"
                        }
                      ]
                      endPoint DEF J3 Solid {
                        translation 0 0 0.33
                        rotation 0 1 0 6.763091915519161e-06
                        children [
                          Shape {
                            appearance DEF J3_material PBRAppearance {
                              baseColor 0.976471 0.85098 0.14902
                              roughness 1
                              metalness 0
                            }
                            geometry DEF j3 Mesh {
                              url [
                                "../protos/LRMate-200iD/meshes/J3.stl"
                              ]
                            }
                          }
                          HingeJoint {
                            jointParameters HingeJointParameters {
                              position -2.098799746822933e-06
                              axis -1 0 0
                              anchor 0.088001 0 0.035027
                            }
                            device [
                              RotationalMotor {
                                name "J4"
                                minPosition -3.1416
                                maxPosition 3.1416
                                maxTorque 10000
                              }
                              PositionSensor {
                                name "J4_sensor"
                              }
                            ]
                            endPoint DEF J4 Solid {
                              translation 0.088001 0 0.035027
                              rotation 1 0 0 2.0988961293291826e-06
                              children [
                                Shape {
                                  appearance DEF J4_material PBRAppearance {
                                    baseColor 0.976471 0.85098 0.14902
                                    roughness 1
                                    metalness 0
                                  }
                                  geometry DEF j4 Mesh {
                                    url [
                                      "../protos/LRMate-200iD/meshes/J4.stl"
                                    ]
                                  }
                                }
                                HingeJoint {
                                  jointParameters HingeJointParameters {
                                    position -1.1634803750855277e-06
                                    axis 0 -1 0
                                    anchor 0.2454 0 0
                                  }
                                  device [
                                    RotationalMotor {
                                      name "J5"
                                      minPosition -2.1817
                                      maxPosition 2.1817
                                      maxTorque 10000
                                    }
                                    PositionSensor {
                                      name "J5_sensor"
                                    }
                                  ]
                                  endPoint DEF J5 Solid {
                                    translation 0.2454 0 0
                                    rotation 0 1 0 1.1634362516369468e-06
                                    children [
                                      Shape {
                                        appearance DEF J5_material PBRAppearance {
                                          baseColor 0.976471 0.85098 0.14902
                                          roughness 1
                                          metalness 0
                                        }
                                        geometry DEF j5 Mesh {
                                          url [
                                            "../protos/LRMate-200iD/meshes/J5.stl"
                                          ]
                                        }
                                      }
                                      HingeJoint {
                                        jointParameters HingeJointParameters {
                                          position 2.1733192381022928e-07
                                          axis -1 0 0
                                          anchor 0.05 0 0
                                        }
                                        device [
                                          RotationalMotor {
                                            name "J6"
                                            maxTorque 10000
                                          }
                                          PositionSensor {
                                            name "J6_sensor"
                                          }
                                        ]
                                        endPoint DEF J6 Solid {
                                          translation 0.05043170818208964 0.0007279321587749775 -0.0004330344255792517
                                          rotation 0.9999516988798764 -0.008443097376022014 -0.0050313034044903795 1.5705820046501155
                                          children [
                                            Solid {
                                              translation 0.0375 0 0
                                              rotation 0 0 1 -1.5707996938995747
                                              children [
                                                DEF Force_sensor_adapter Shape {
                                                  appearance PBRAppearance {
                                                    baseColor 0.529412 0.54902 0.54902
                                                  }
                                                  geometry Mesh {
                                                    url [
                                                      "../Workpieces/Force_sensor_transfer.stl"
                                                    ]
                                                  }
                                                }
                                                Solid {
                                                  translation 0 0.007 0
                                                  rotation 1 0 0 -1.5708003061004252
                                                  children [
                                                    Solid {
                                                      translation 0 0 0.0425
                                                      rotation 1 0 0 1.5708003061004252
                                                      children [
                                                        Pose {
                                                          rotation 0 1 0 1.5707996938995747
                                                          children [
                                                            Solid {
                                                              translation 0 0.0159 0
                                                              rotation 0 1 0 1.5707996938995747
                                                              children [
                                                                DEF workpiece Shape {
                                                                  appearance PBRAppearance {
                                                                    baseColor 0.529412 0.54902 0.54902
                                                                  }
                                                                  geometry Mesh {
                                                                    url [
                                                                      "../Workpieces/Flat.stl"
                                                                    ]
                                                                  }
                                                                }
                                                              ]
                                                              contactMaterial "Aluminum alloy"
                                                              boundingObject USE workpiece
                                                              physics Physics {
                                                                density 0.01
                                                              }
                                                            }
                                                            DEF workpiece_transfer Shape {
                                                              appearance PBRAppearance {
                                                              }
                                                              geometry Mesh {
                                                                url [
                                                                  "../Workpieces/Workpiece_transfer.stl"
                                                                ]
                                                              }
                                                            }
                                                          ]
                                                        }
                                                      ]
                                                      boundingObject Pose {
                                                        rotation 0 1 0 1.5707996938995747
                                                        children [
                                                          USE workpiece_transfer
                                                        ]
                                                      }
                                                      physics Physics {
                                                        mass 0.1
                                                      }
                                                    }
                                                    DEF sensor Shape {
                                                      appearance PBRAppearance {
                                                        baseColor 1 0.643137 0.643137
                                                      }
                                                      geometry Mesh {
                                                        url [
                                                          "../Workpieces/WEF-6A200-20-RCD-B (2).stl"
                                                        ]
                                                      }
                                                    }
                                                  ]
                                                  name "solid(1)"
                                                  boundingObject USE sensor
                                                  physics Physics {
                                                    mass 0.1
                                                  }
                                                }
                                              ]
                                              boundingObject USE Force_sensor_adapter
                                              physics Physics {
                                                density 0.01
                                                mass 1
                                              }
                                            }
                                            Shape {
                                              appearance DEF J6_material PBRAppearance {
                                                baseColor 0.529412 0.54902 0.54902
                                                roughness 1
                                                metalness 0
                                              }
                                              geometry DEF j6 Mesh {
                                                url [
                                                  "../protos/LRMate-200iD/meshes/J6.stl"
                                                ]
                                              }
                                            }
                                          ]
                                          name "J6"
                                          boundingObject USE j6
                                          physics Physics {
                                            density -1
                                            mass 0.093213
                                            centerOfMass [
                                              0.012509 0 -2.8e-05
                                            ]
                                            inertiaMatrix [
                                              5.265445e-05 3.158696e-05 3.162813e-05
                                              3.914555e-14 3.436607e-08 2.756904e-11
                                            ]
                                          }
                                        }
                                      }
                                    ]
                                    name "J5"
                                    boundingObject USE j5
                                    physics Physics {
                                      density -1
                                      mass 0.353026
                                      centerOfMass [
                                        0.00558 0.003772 -7.4e-05
                                      ]
                                      inertiaMatrix [
                                        0.0002449525 0.000329224 0.0003046354
                                        1.182355e-05 2.002576e-07 -1.143489e-08
                                      ]
                                    }
                                  }
                                }
                              ]
                              name "J4"
                              boundingObject USE j4
                              physics Physics {
                                density -1
                                mass 0.000826
                                centerOfMass [
                                  0.108899 0.008914 0.05615
                                ]
                                inertiaMatrix [
                                  2.656732e-08 2.710462e-08 4.124432e-08
                                  -1.065332e-19 2.78672e-24 2.3309e-24
                                ]
                              }
                            }
                          }
                        ]
                        name "J3"
                        boundingObject USE j3
                        physics Physics {
                          density -1
                          mass 2.394262
                          centerOfMass [
                            0.008237 0.00068 0.017646
                          ]
                          inertiaMatrix [
                            0.006334728 0.00732802 0.007260425
                            -4.950446e-05 -0.0007613547 -6.64726e-05
                          ]
                        }
                      }
                    }
                  ]
                  name "J2"
                  boundingObject USE j2
                  physics Physics {
                    density -1
                    mass 6.361362
                    centerOfMass [
                      -0.007993 -0.001801 0.121256
                    ]
                    inertiaMatrix [
                      0.1066513 0.08706777 0.03170156
                      8.068216e-05 0.001451138 -0.0005574152
                    ]
                  }
                }
              }
            ]
            name "J1"
            boundingObject USE j1
            physics Physics {
              density -1
              mass 14.354858
              centerOfMass [
                0.039191 -0.000668 0.318431
              ]
              inertiaMatrix [
                0.9059617 0.9590944 0.1326389
                -0.0006305855 -0.1324298 -0.0008315873
              ]
            }
          }
        }
      ]
      name "LRMate-200iD"
      boundingObject USE base
      physics Physics {
        density -1
        mass 4.853289
        centerOfMass [
          -0.006827 0.080423 0.000322
        ]
        inertiaMatrix [
          0.02198661 0.02280118 0.02382922
          0.0001430305 0.0001185041 3.060087e-05
        ]
      }
      controller "controller_itri"
      supervisor TRUE
    }
  ]
  controller "<none>"
  supervisor TRUE
}
DEF box Solid {
  translation 2.588210000034056 -0.006567241267240753 0.39994114002838543
  rotation 8.058813041766802e-19 4.870228793427787e-17 0.9999999999999999 -3.1408923578507197
  children [
    DEF BOX_SHAPE Shape {
      appearance PBRAppearance {
        baseColorMap ImageTexture {
          url [
            "https://raw.githubusercontent.com/cyberbotics/webots/R2025a/projects/objects/factory/containers/protos/textures/wooden_box_base_color.jpg"
          ]
        }
        roughnessMap ImageTexture {
          url [
            "https://raw.githubusercontent.com/cyberbotics/webots/R2025a/projects/objects/factory/containers/protos/textures/wooden_box_roughness.jpg"
          ]
        }
        metalness 0
        normalMap ImageTexture {
          url [
            "https://raw.githubusercontent.com/cyberbotics/webots/R2025a/projects/objects/factory/containers/protos/textures/wooden_box_normal.jpg"
          ]
        }
        occlusionMap ImageTexture {
          url [
            "https://raw.githubusercontent.com/cyberbotics/webots/R2025a/projects/objects/factory/containers/protos/textures/wooden_box_occlusion.jpg"
          ]
        }
      }
      geometry Box {
        size 0.5 0.5 0.8
      }
    }
  ]
  name "wooden box"
  model "wooden box"
  boundingObject USE BOX_SHAPE
  physics Physics {
    density -1
    mass 0.3
    centerOfMass [
      0 0 0
    ]
    inertiaMatrix [
      0.022250000000000002 0.022250000000000002 0.0125
      0 0 0
    ]
  }
}
Robot {
  translation 0.673922 -0.00208465 0.61305
  rotation 1 0 0 1.5708003061004252
  children [
    HingeJoint {
      jointParameters HingeJointParameters {
        axis 0 0 1
      }
      device [
        DEF wheel_motor_2 RotationalMotor {
          name "wheel_motor_2"
          maxVelocity 30
        }
      ]
      endPoint DEF grinding_wheel Solid {
        children [
          Solid {
            translation 3.559647107997943e-05 -0.00010027911066512463 -5.767289666974446e-05
            rotation -0.20439497571287843 -0.5521100467659951 0.8083298770696171 5.521370990498962e-06
            children [
              DEF wheel Shape {
                appearance PBRAppearance {
                }
                geometry Cylinder {
                  height 0.05
                  radius 0.06
                }
              }
              TouchSensor {
                translation 3.5594772482716586e-05 -9.71366395529083e-05 -5.7671578710647136e-05
                rotation -0.20428161464581907 -0.5520977225620943 0.8083669504992431 5.521008297210747e-06
                name "force sensor"
                boundingObject Cylinder {
                  height 0.05
                  radius 0.06
                }
                physics Physics {
                  density 0.01
                }
                type "force-3d"
              }
            ]
            boundingObject Box {
              size 0.05 0.1 0.04
            }
            physics Physics {
              mass 0.1
            }
          }
          Pose {
            translation -0.06 0 0
            rotation 0 1 0 1.5708003061004252
          }
        ]
      }
    }
  ]
  name "robot(1)"
  contactMaterial "Aluminum Oxide"
  boundingObject USE wheel
  controller "<none>"
  supervisor TRUE
}
DEF BELT_TARGET Pose {
  translation 0.614 -0.002 0.613
  rotation 0 1 0 1.5707996938995747
}
Robot {
  children [
    DEF grinder Solid {
      translation 0.93 0.185 -0.0006264107883857256
      rotation 0 0 1 3.141592653589793
      children [
        Solid {
          translation -5.143503540250283e-05 -1.8933227527717644e-06 -0.001483501809758675
          rotation 0.6546688548142531 -0.4315899191969425 -0.6205955463776476 1.7388959201076813e-05
          children [
            DEF grinding_wheel Solid {
              translation 0.256 0.187 0.614
              rotation 1 0 0 1.5708031102103517
              children [
                Solid {
                  translation -0.06 0 0
                  children [
                    Shape {
                      appearance PBRAppearance {
                      }
                      geometry Sphere {
                        radius 0.01
                      }
                    }
                  ]
                }
                Pose {
                  translation -0.06 0 0
                  rotation 0 1 0 1.5708003061004252
                }
              ]
              name "solid(2)"
              contactMaterial ""
            }
            Solid {
              children [
                Pose {
                  translation 0.31 -0.185 0.64
                  rotation 0.37796390461552926 -0.6546538347889604 0.6546538347889604 2.41886
                }
                Solid {
                  children [
                    Shape {
                      appearance PBRAppearance {
                        baseColor 0.529412 0.54902 0.54902
                      }
                      geometry DEF Grinder_Right Mesh {
                        url [
                          "../workpiece/Grinder_RightBelt.stl"
                        ]
                      }
                    }
                  ]
                }
                Shape {
                  appearance PBRAppearance {
                    baseColor 0.529412 0.54902 0.54902
                  }
                  geometry DEF Grinder_Left Mesh {
                    url [
                      "../workpiece/Grinder_LeftBelt.stl"
                    ]
                  }
                }
              ]
            }
            Shape {
              appearance PBRAppearance {
                baseColor 0.976471 0.85098 0.14902
              }
              geometry DEF Grinder_Shell Mesh {
                url [
                  "../workpiece/Grinder_Shell.stl"
                ]
              }
            }
          ]
          boundingObject USE Grinder_Shell
          physics Physics {
          }
        }
        Shape {
          appearance PBRAppearance {
            baseColor 0.976471 0.85098 0.14902
          }
          geometry DEF Grinder_Bottom Mesh {
            url [
              "../workpiece/Grinder_Bottom.stl"
            ]
          }
        }
      ]
      name "solid(1)"
      boundingObject USE Grinder_Bottom
      physics Physics {
        mass 4
      }
    }
  ]
  name "robot(2)"
  controller "<none>"
}
