#VRML_SIM R2025a utf8

EXTERNPROTO "https://raw.githubusercontent.com/cyberbotics/webots/R2025a/projects/objects/backgrounds/protos/TexturedBackground.proto"
EXTERNPROTO "https://raw.githubusercontent.com/cyberbotics/webots/R2025a/projects/objects/floors/protos/Floor.proto"
EXTERNPROTO "https://raw.githubusercontent.com/cyberbotics/webots/R2025a/projects/objects/backgrounds/protos/TexturedBackgroundLight.proto"

WorldInfo {
}
Viewpoint {
  orientation 0.14799595311170632 -0.3163239440834737 -0.9370359439541436 5.356991376991042
  position -1.6749699735782675 -1.7966681164803986 1.042611037902004
}
TexturedBackground {
  skyColor [
    1 1 1
  ]
}
Floor {
}
Robot {
  children [
    DEF BODY Pose {
      translation 0 0 0.4
      children [
        Shape {
          appearance PBRAppearance {
            baseColor 0.529412 0.54902 0.54902
            roughness 1
            metalness 0
          }
          geometry Box {
            size 0.1 0.4 0.7
          }
        }
      ]
    }
    HingeJoint {
      jointParameters HingeJointParameters {
        axis 0 1 0
        anchor 0 -0.22 0.1
      }
      device [
        RotationalMotor {
          name "motor_1"
        }
      ]
      endPoint Solid {
        translation 0 -0.22 0.1
        rotation 1 0 0 1.5707996938995747
        children [
          DEF wheel_1 Shape {
            appearance PBRAppearance {
              roughness 1
              metalness 0
            }
            geometry Cylinder {
              height 0.05
              radius 0.1
            }
          }
        ]
        boundingObject USE wheel_1
        physics Physics {
        }
      }
    }
    HingeJoint {
      jointParameters HingeJointParameters {
        axis 0 1 0
        anchor 0 0.22 0.1
      }
      device [
        RotationalMotor {
          name "motor_2"
        }
      ]
      endPoint Solid {
        translation 0 0.22 0.1
        rotation -1 0 0 1.5707996938995747
        children [
          USE wheel_1
        ]
        name "solid(1)"
        boundingObject USE wheel_1
        physics Physics {
        }
      }
    }
  ]
  physics Physics {
  }
  controller "controller_daniel"
  supervisor TRUE
}
TexturedBackgroundLight {
}
