#VRML_SIM R2025a utf8

EXTERNPROTO "https://raw.githubusercontent.com/cyberbotics/webots/R2025a/projects/objects/backgrounds/protos/TexturedBackgroundLight.proto"

WorldInfo {
}
Viewpoint {
  orientation 0.31059645520343776 0.4229340880308592 -0.8512676425170667 0.8404933658552826
  position -0.5639585154315372 0.10240081142898323 0.7460132226051254
}
Background {
  skyColor [
    0.494118 0.6 0.717647
  ]
}
TexturedBackgroundLight {
  castShadows FALSE
}
Solid {
  children [
    Shape {
      appearance PBRAppearance {
        baseColorMap ImageTexture {
          url [
            "https://raw.githubusercontent.com/cyberbotics/webots/R2025a/projects/appearances/protos/textures/parquetry/chequered_parquetry_base_color.jpg"
          ]
        }
        roughness 1
        roughnessMap ImageTexture {
          url [
            "https://raw.githubusercontent.com/cyberbotics/webots/R2025a/projects/appearances/protos/textures/parquetry/chequered_parquetry_roughness.jpg"
          ]
        }
        metalness 0
        normalMap ImageTexture {
          url [
            "https://raw.githubusercontent.com/cyberbotics/webots/R2025a/projects/appearances/protos/textures/parquetry/chequered_parquetry_normal.jpg"
          ]
        }
        occlusionMap ImageTexture {
          url [
            "https://raw.githubusercontent.com/cyberbotics/webots/R2025a/projects/appearances/protos/textures/parquetry/chequered_parquetry_occlusion.jpg"
          ]
        }
      }
      geometry IndexedFaceSet {
        coord Coordinate {
          point [
            -5 -5 0
            5 -5 0
            -5 5 0
            5 5 0
          ]
        }
        texCoord TextureCoordinate {
          point [
            0 0
            20 0
            0 20
            20 20
          ]
        }
        coordIndex [
          2, 0, 1, 3, -1
        ]
        texCoordIndex [
          2, 0, 1, 3, -1
        ]
      }
    }
  ]
  name "floor"
  model "floor"
  boundingObject Plane {
    size 10 10
  }
  locked TRUE
}
Robot {
  rotation 0 0 1 3.14159
  children [
    Robot {
      translation -0.0056008927226052115 3.693212538796337e-05 -0.010222661988009344
      rotation 0.2028040119546028 -0.9701052587223848 -0.1332903587447053 0.0032813888807565997
      children [
        Shape {
          appearance DEF Base_material PBRAppearance {
            baseColor 0.792157 0.819608 0.933333
            roughness 1
            metalness 0
          }
          geometry DEF base Mesh {
            url [
              "C:/Users/vivian/OneDrive - NTHU/桌面/ITRI/webot_practice_2025ver/protos/LRMate-200iD/meshes/base.stl"
            ]
          }
        }
        HingeJoint {
          jointParameters HingeJointParameters {
            position -2.7046057849127806e-05
            axis 0 0 1
            anchor 0 0 0.042741
          }
          device [
            DEF J1 RotationalMotor {
              name "J1"
              minPosition -2.9671
              maxPosition 2.9671
              maxTorque 10000
            }
            PositionSensor {
              name "J1_sensor"
            }
          ]
          endPoint Solid {
            translation 0 0 0.042741
            rotation 0 0 -1 2.704606321854357e-05
            children [
              Shape {
                appearance DEF J1_material PBRAppearance {
                  baseColor 0.792157 0.819608 0.933333
                  roughness 1
                  metalness 0
                }
                geometry DEF j1 Mesh {
                  url [
                    "C:/Users/vivian/OneDrive - NTHU/桌面/ITRI/webot_practice_2025ver/protos/LRMate-200iD/meshes/j1.stl"
                  ]
                }
              }
              HingeJoint {
                jointParameters HingeJointParameters {
                  position 0.0005653679934835649
                  axis 0 -1 0
                  anchor 0.05 0 0.28726
                }
                device [
                  RotationalMotor {
                    name "J2"
                    minPosition -2.5307
                    maxPosition 1.7453
                    maxTorque 10000
                  }
                  PositionSensor {
                    name "J2_sensor"
                  }
                ]
                endPoint Solid {
                  translation 0.05 0 0.28726
                  rotation 0 -0.9999999999999999 0 0.0005653679936717758
                  children [
                    Shape {
                      appearance DEF J2_material PBRAppearance {
                        baseColor 0.792157 0.819608 0.933333
                        roughness 1
                        metalness 0
                      }
                      geometry DEF j2 Mesh {
                        url [
                          "C:/Users/vivian/OneDrive - NTHU/桌面/ITRI/webot_practice_2025ver/protos/LRMate-200iD/meshes/j2.stl"
                        ]
                      }
                    }
                    HingeJoint {
                      jointParameters HingeJointParameters {
                        position 2.068348649438287e-05
                        axis 0 -1 0
                        anchor 0 0 0.33
                      }
                      device [
                        RotationalMotor {
                          name "J3"
                          minPosition -1.2217
                          maxPosition 3.5779
                          maxTorque 10000
                        }
                        PositionSensor {
                          name "J3_sensor"
                        }
                      ]
                      endPoint Solid {
                        translation 0 0 0.33
                        rotation 0 -1 0 2.068347734027122e-05
                        children [
                          Shape {
                            appearance DEF J3_material PBRAppearance {
                              baseColor 0.792157 0.819608 0.933333
                              roughness 1
                              metalness 0
                            }
                            geometry DEF j3 Mesh {
                              url [
                                "C:/Users/vivian/OneDrive - NTHU/桌面/ITRI/webot_practice_2025ver/protos/LRMate-200iD/meshes/j3.stl"
                              ]
                            }
                          }
                          HingeJoint {
                            jointParameters HingeJointParameters {
                              position 1.6377454412953185e-06
                              axis -1 0 0
                              anchor 0.088001 0 0.035027
                            }
                            device [
                              RotationalMotor {
                                name "J4"
                                minPosition -3.1416
                                maxPosition 3.1416
                                maxTorque 10000
                              }
                              PositionSensor {
                                name "J4_sensor"
                              }
                            ]
                            endPoint Solid {
                              translation 0.088001 0 0.035027
                              rotation -1 0 0 1.6377725200694167e-06
                              children [
                                Shape {
                                  appearance DEF J4_material PBRAppearance {
                                    baseColor 0.529412 0.54902 0.54902
                                    roughness 1
                                    metalness 0
                                  }
                                  geometry DEF j4 Mesh {
                                    url [
                                      "C:/Users/vivian/OneDrive - NTHU/桌面/ITRI/webot_practice_2025ver/protos/LRMate-200iD/meshes/j4.stl"
                                    ]
                                  }
                                }
                                HingeJoint {
                                  jointParameters HingeJointParameters {
                                    position -2.108649338596204e-05
                                    axis 0 -1 0
                                    anchor 0.2454 0 0
                                  }
                                  device [
                                    RotationalMotor {
                                      name "J5"
                                      minPosition -2.1817
                                      maxPosition 2.1817
                                      maxTorque 10000
                                    }
                                    PositionSensor {
                                      name "J5_sensor"
                                    }
                                  ]
                                  endPoint Solid {
                                    translation 0.2454 0 0
                                    rotation 0 1 0 2.1086485730780167e-05
                                    children [
                                      Shape {
                                        appearance DEF J5_material PBRAppearance {
                                          baseColor 0.792157 0.819608 0.933333
                                          roughness 1
                                          metalness 0
                                        }
                                        geometry DEF j5 Mesh {
                                          url [
                                            "C:/Users/vivian/OneDrive - NTHU/桌面/ITRI/webot_practice_2025ver/protos/LRMate-200iD/meshes/j5.stl"
                                          ]
                                        }
                                      }
                                      HingeJoint {
                                        jointParameters HingeJointParameters {
                                          position 3.3959834973452594e-05
                                          axis -1 0 0
                                          anchor 0.05 0 0
                                        }
                                        device [
                                          RotationalMotor {
                                            name "J6"
                                            maxTorque 10000
                                          }
                                          PositionSensor {
                                            name "J6_sensor"
                                          }
                                        ]
                                        endPoint Solid {
                                          translation 0.05 0 0
                                          rotation 1 0 0 1.5707660397908607
                                          children [
                                            DEF touch_sensor TouchSensor {
                                              translation 0.028342993012482665 -0.00012483566090615295 -1.424279411512021e-05
                                              rotation 0.04284587317569295 0.04134261250084431 -0.9982259361203841 3.3813294905749133e-07
                                              boundingObject Box {
                                                size 0.005 0.04 0.04
                                              }
                                              physics Physics {
                                              }
                                              type "force-3d"
                                            }
                                            Shape {
                                              appearance DEF J6_material PBRAppearance {
                                                baseColor 0.792157 0.819608 0.933333
                                                roughness 1
                                                metalness 0
                                              }
                                              geometry DEF j6 Mesh {
                                                url [
                                                  "C:/Users/vivian/OneDrive - NTHU/桌面/ITRI/webot_practice_2025ver/protos/LRMate-200iD/meshes/j6.stl"
                                                ]
                                              }
                                            }
                                          ]
                                          name "J6"
                                          boundingObject USE j6
                                          physics Physics {
                                            density -1
                                            mass 0.093213
                                            centerOfMass [
                                              0.012509 0 -2.8e-05
                                            ]
                                            inertiaMatrix [
                                              5.265445e-05 3.158696e-05 3.162813e-05
                                              3.914555e-14 3.436607e-08 2.756904e-11
                                            ]
                                          }
                                        }
                                      }
                                    ]
                                    name "J5"
                                    boundingObject USE j5
                                    physics Physics {
                                      density -1
                                      mass 0.353026
                                      centerOfMass [
                                        0.00558 0.003772 -7.4e-05
                                      ]
                                      inertiaMatrix [
                                        0.0002449525 0.000329224 0.0003046354
                                        1.182355e-05 2.002576e-07 -1.143489e-08
                                      ]
                                    }
                                  }
                                }
                              ]
                              name "J4"
                              boundingObject USE j4
                              physics Physics {
                                density -1
                                mass 0.000826
                                centerOfMass [
                                  0.108899 0.008914 0.05615
                                ]
                                inertiaMatrix [
                                  2.656732e-08 2.710462e-08 4.124432e-08
                                  -1.065332e-19 2.78672e-24 2.3309e-24
                                ]
                              }
                            }
                          }
                        ]
                        name "J3"
                        boundingObject USE j3
                        physics Physics {
                          density -1
                          mass 2.394262
                          centerOfMass [
                            0.008237 0.00068 0.017646
                          ]
                          inertiaMatrix [
                            0.006334728 0.00732802 0.007260425
                            -4.950446e-05 -0.0007613547 -6.64726e-05
                          ]
                        }
                      }
                    }
                  ]
                  name "J2"
                  boundingObject USE j2
                  physics Physics {
                    density -1
                    mass 6.361362
                    centerOfMass [
                      -0.007993 -0.001801 0.121256
                    ]
                    inertiaMatrix [
                      0.1066513 0.08706777 0.03170156
                      8.068216e-05 0.001451138 -0.0005574152
                    ]
                  }
                }
              }
            ]
            name "J1"
            boundingObject USE j1
            physics Physics {
              density -1
              mass 14.354858
              centerOfMass [
                0.039191 -0.000668 0.318431
              ]
              inertiaMatrix [
                0.9059617 0.9590944 0.1326389
                -0.0006305855 -0.1324298 -0.0008315873
              ]
            }
          }
        }
      ]
      name "LRMate-200iD"
      boundingObject USE base
      physics Physics {
        density -1
        mass 4.853289
        centerOfMass [
          -0.006827 0.080423 0.000322
        ]
        inertiaMatrix [
          0.02198661 0.02280118 0.02382922
          0.0001430305 0.0001185041 3.060087e-05
        ]
      }
      controller "my_controller_2"
      supervisor TRUE
    }
  ]
  controller "<none>"
  supervisor TRUE
}
Solid {
  translation 1.44666 0.01084609999999985 0.38744320000000015
  rotation -1.0281145697801293e-17 1.3416724144692243e-16 1 3.1415926535897913
  children [
    DEF BOX_SHAPE Shape {
      appearance PBRAppearance {
        baseColorMap ImageTexture {
          url [
            "https://raw.githubusercontent.com/cyberbotics/webots/R2025a/projects/objects/factory/containers/protos/textures/wooden_box_base_color.jpg"
          ]
        }
        roughnessMap ImageTexture {
          url [
            "https://raw.githubusercontent.com/cyberbotics/webots/R2025a/projects/objects/factory/containers/protos/textures/wooden_box_roughness.jpg"
          ]
        }
        metalness 0
        normalMap ImageTexture {
          url [
            "https://raw.githubusercontent.com/cyberbotics/webots/R2025a/projects/objects/factory/containers/protos/textures/wooden_box_normal.jpg"
          ]
        }
        occlusionMap ImageTexture {
          url [
            "https://raw.githubusercontent.com/cyberbotics/webots/R2025a/projects/objects/factory/containers/protos/textures/wooden_box_occlusion.jpg"
          ]
        }
      }
      geometry Box {
        size 0.2 0.2 0.8
      }
    }
  ]
  name "wooden box"
  model "wooden box"
  boundingObject USE BOX_SHAPE
  physics Physics {
  }
}
DEF box Solid {
  translation -1.27 0 0.68
  children [
    DEF BOX_SHAPE Shape {
      appearance PBRAppearance {
        baseColorMap ImageTexture {
          url [
            "https://raw.githubusercontent.com/cyberbotics/webots/R2025a/projects/objects/factory/containers/protos/textures/wooden_box_base_color.jpg"
          ]
        }
        roughnessMap ImageTexture {
          url [
            "https://raw.githubusercontent.com/cyberbotics/webots/R2025a/projects/objects/factory/containers/protos/textures/wooden_box_roughness.jpg"
          ]
        }
        metalness 0
        normalMap ImageTexture {
          url [
            "https://raw.githubusercontent.com/cyberbotics/webots/R2025a/projects/objects/factory/containers/protos/textures/wooden_box_normal.jpg"
          ]
        }
        occlusionMap ImageTexture {
          url [
            "https://raw.githubusercontent.com/cyberbotics/webots/R2025a/projects/objects/factory/containers/protos/textures/wooden_box_occlusion.jpg"
          ]
        }
      }
      geometry Box {
        size 0.1 0.1 0.1
      }
    }
  ]
  name "wooden box(1)"
  model "wooden box"
  boundingObject USE BOX_SHAPE
}
Solid {
  translation -0.64 -0.01 0.7
  rotation 0 0 1 1.5707963267948968
  children [
    Shape {
      appearance PBRAppearance {
      }
      geometry Mesh {
        url [
          "../../../../文件/NTHU/NEAF/工研院計畫/研磨/研磨標準件/平面標準件_m.stl"
        ]
      }
    }
  ]
}
