#VRML_SIM R2025a utf8

EXTERNPROTO "https://raw.githubusercontent.com/cyberbotics/webots/R2025a/projects/objects/backgrounds/protos/TexturedBackgroundLight.proto"

WorldInfo {
}
Viewpoint {
  orientation -0.05182377528273515 -0.032836522152450615 0.998116255317173 4.269434744293206
  position -0.07942436249340433 0.98213406090691 0.8111259000442387
}
Background {
  skyColor [
    0.494118 0.6 0.717647
  ]
}
TexturedBackgroundLight {
  castShadows FALSE
}
Solid {
  children [
    Shape {
      appearance PBRAppearance {
        baseColorMap ImageTexture {
          url [
            "https://raw.githubusercontent.com/cyberbotics/webots/R2025a/projects/appearances/protos/textures/parquetry/chequered_parquetry_base_color.jpg"
          ]
        }
        roughness 1
        roughnessMap ImageTexture {
          url [
            "https://raw.githubusercontent.com/cyberbotics/webots/R2025a/projects/appearances/protos/textures/parquetry/chequered_parquetry_roughness.jpg"
          ]
        }
        metalness 0
        normalMap ImageTexture {
          url [
            "https://raw.githubusercontent.com/cyberbotics/webots/R2025a/projects/appearances/protos/textures/parquetry/chequered_parquetry_normal.jpg"
          ]
        }
        occlusionMap ImageTexture {
          url [
            "https://raw.githubusercontent.com/cyberbotics/webots/R2025a/projects/appearances/protos/textures/parquetry/chequered_parquetry_occlusion.jpg"
          ]
        }
      }
      geometry IndexedFaceSet {
        coord Coordinate {
          point [
            -5 -5 0
            5 -5 0
            -5 5 0
            5 5 0
          ]
        }
        texCoord TextureCoordinate {
          point [
            0 0
            20 0
            0 20
            20 20
          ]
        }
        coordIndex [
          2, 0, 1, 3, -1
        ]
        texCoordIndex [
          2, 0, 1, 3, -1
        ]
      }
    }
  ]
  name "floor"
  model "floor"
  boundingObject Plane {
    size 10 10
  }
  locked TRUE
}
Robot {
  rotation 0 0 1 3.14159
  children [
    DEF LRMate200iD Robot {
      translation -0.005600960923301844 3.8101818316042396e-05 -0.014740320705127338
      rotation 0.3082718242297126 -0.9411106945312951 -0.13884935370720342 0.003149010604528581
      children [
        Shape {
          appearance DEF Base_material PBRAppearance {
            baseColor 0.529412 0.54902 0.54902
            roughness 1
            metalness 0
          }
          geometry DEF base Mesh {
            url [
              "C:/Users/vivian/OneDrive - NTHU/桌面/ITRI/webot_practice_2025ver/protos/LRMate-200iD/meshes/base.stl"
            ]
          }
        }
        HingeJoint {
          jointParameters HingeJointParameters {
            position -2.6999742961575552e-09
            axis 0 0 1
            anchor 0 0 0.042741
          }
          device [
            DEF J1 RotationalMotor {
              name "J1"
              minPosition -2.9671
              maxPosition 2.9671
              maxTorque 10000
            }
            PositionSensor {
              name "J1_sensor"
            }
          ]
          endPoint DEF J1 Solid {
            translation 0 0 0.042741
            children [
              Shape {
                appearance DEF J1_material PBRAppearance {
                  baseColor 0.976471 0.85098 0.14902
                  roughness 1
                  metalness 0
                }
                geometry DEF j1 Mesh {
                  url [
                    "C:/Users/vivian/OneDrive - NTHU/桌面/ITRI/webot_practice_2025ver/protos/LRMate-200iD/meshes/j1.stl"
                  ]
                }
              }
              HingeJoint {
                jointParameters HingeJointParameters {
                  position -6.043859909226363e-06
                  axis 0 -1 0
                  anchor 0.05 0 0.28726
                }
                device [
                  RotationalMotor {
                    name "J2"
                    minPosition -2.5307
                    maxPosition 1.7453
                    maxTorque 10000
                  }
                  PositionSensor {
                    name "J2_sensor"
                  }
                ]
                endPoint DEF J2 Solid {
                  translation 0.05 0 0.28726
                  rotation 0 1 0 6.043849259125748e-06
                  children [
                    Shape {
                      appearance DEF J2_material PBRAppearance {
                        baseColor 0.976471 0.85098 0.14902
                        roughness 1
                        metalness 0
                      }
                      geometry DEF j2 Mesh {
                        url [
                          "C:/Users/vivian/OneDrive - NTHU/桌面/ITRI/webot_practice_2025ver/protos/LRMate-200iD/meshes/j2.stl"
                        ]
                      }
                    }
                    HingeJoint {
                      jointParameters HingeJointParameters {
                        position -7.074081166080334e-06
                        axis 0 -1 0
                        anchor 0 0 0.33
                      }
                      device [
                        RotationalMotor {
                          name "J3"
                          minPosition -1.2217
                          maxPosition 3.5779
                          maxTorque 10000
                        }
                        PositionSensor {
                          name "J3_sensor"
                        }
                      ]
                      endPoint DEF J3 Solid {
                        translation 0 0 0.33
                        rotation 0 0.9999999999999999 0 7.074082039474545e-06
                        children [
                          Shape {
                            appearance DEF J3_material PBRAppearance {
                              baseColor 0.976471 0.85098 0.14902
                              roughness 1
                              metalness 0
                            }
                            geometry DEF j3 Mesh {
                              url [
                                "C:/Users/vivian/OneDrive - NTHU/桌面/ITRI/webot_practice_2025ver/protos/LRMate-200iD/meshes/j3.stl"
                              ]
                            }
                          }
                          HingeJoint {
                            jointParameters HingeJointParameters {
                              position 0.0001978494070780394
                              axis -1 0 0
                              anchor 0.088001 0 0.035027
                            }
                            device [
                              RotationalMotor {
                                name "J4"
                                minPosition -3.1416
                                maxPosition 3.1416
                                maxTorque 10000
                              }
                              PositionSensor {
                                name "J4_sensor"
                              }
                            ]
                            endPoint DEF J4 Solid {
                              translation 0.088001 0 0.035027
                              rotation -1 0 0 0.00019784940790216872
                              children [
                                Shape {
                                  appearance DEF J4_material PBRAppearance {
                                    baseColor 0.976471 0.85098 0.14902
                                    roughness 1
                                    metalness 0
                                  }
                                  geometry DEF j4 Mesh {
                                    url [
                                      "C:/Users/vivian/OneDrive - NTHU/桌面/ITRI/webot_practice_2025ver/protos/LRMate-200iD/meshes/j4.stl"
                                    ]
                                  }
                                }
                                HingeJoint {
                                  jointParameters HingeJointParameters {
                                    position -1.0473583040455012e-06
                                    axis 0 -1 0
                                    anchor 0.2454 0 0
                                  }
                                  device [
                                    RotationalMotor {
                                      name "J5"
                                      minPosition -2.1817
                                      maxPosition 2.1817
                                      maxTorque 10000
                                    }
                                    PositionSensor {
                                      name "J5_sensor"
                                    }
                                  ]
                                  endPoint DEF J5 Solid {
                                    translation 0.2454 0 0
                                    rotation 0 1 0 1.0473301047566997e-06
                                    children [
                                      Shape {
                                        appearance DEF J5_material PBRAppearance {
                                          baseColor 0.976471 0.85098 0.14902
                                          roughness 1
                                          metalness 0
                                        }
                                        geometry DEF j5 Mesh {
                                          url [
                                            "C:/Users/vivian/OneDrive - NTHU/桌面/ITRI/webot_practice_2025ver/protos/LRMate-200iD/meshes/j5.stl"
                                          ]
                                        }
                                      }
                                      HingeJoint {
                                        jointParameters HingeJointParameters {
                                          position -6.709969025855664e-06
                                          axis -1 0 0
                                          anchor 0.05 0 0
                                        }
                                        device [
                                          RotationalMotor {
                                            name "J6"
                                            maxTorque 10000
                                          }
                                          PositionSensor {
                                            name "J6_sensor"
                                          }
                                        ]
                                        endPoint DEF J6 Solid {
                                          translation 0.05 0 0
                                          rotation 1 0 0 1.570806705677233
                                          children [
                                            Solid {
                                              translation 0.03 0 0
                                              rotation 0 0 1 -1.5707996938995747
                                              children [
                                                TouchSensor {
                                                  translation 8.24134010912747e-06 -2.6597593683064247e-08 6.224939887340686e-09
                                                  rotation 0.03466204237817686 0.019762225655802608 0.9992036815661274 1.221781936917534e-10
                                                  children [
                                                    DEF flat_workpiece Solid {
                                                      translation 0 0.0325 0
                                                      children [
                                                        Shape {
                                                          appearance PBRAppearance {
                                                            baseColor 0.447059 0.462745 0.462745
                                                          }
                                                          geometry DEF flat Mesh {
                                                            url [
                                                              "../workpiece/flat_Ccm.stl"
                                                            ]
                                                          }
                                                        }
                                                      ]
                                                      boundingObject USE flat
                                                      physics Physics {
                                                      }
                                                    }
                                                    Shape {
                                                      appearance PBRAppearance {
                                                        baseColor 1 0.643137 0.643137
                                                      }
                                                      geometry DEF force_sensor Mesh {
                                                        url [
                                                          "../workpiece/force sensor_Cm.stl"
                                                        ]
                                                      }
                                                    }
                                                  ]
                                                  boundingObject USE force_sensor
                                                  physics Physics {
                                                  }
                                                  type "force-3d"
                                                }
                                              ]
                                              boundingObject USE force_sensor
                                              physics Physics {
                                              }
                                            }
                                            Shape {
                                              appearance DEF J6_material PBRAppearance {
                                                baseColor 0.529412 0.54902 0.54902
                                                roughness 1
                                                metalness 0
                                              }
                                              geometry DEF j6 Mesh {
                                                url [
                                                  "C:/Users/vivian/OneDrive - NTHU/桌面/ITRI/webot_practice_2025ver/protos/LRMate-200iD/meshes/j6.stl"
                                                ]
                                              }
                                            }
                                          ]
                                          name "J6"
                                          boundingObject USE j6
                                          physics Physics {
                                            density -1
                                            mass 0.093213
                                            centerOfMass [
                                              0.012509 0 -2.8e-05
                                            ]
                                            inertiaMatrix [
                                              5.265445e-05 3.158696e-05 3.162813e-05
                                              3.914555e-14 3.436607e-08 2.756904e-11
                                            ]
                                          }
                                        }
                                      }
                                    ]
                                    name "J5"
                                    boundingObject USE j5
                                    physics Physics {
                                      density -1
                                      mass 0.353026
                                      centerOfMass [
                                        0.00558 0.003772 -7.4e-05
                                      ]
                                      inertiaMatrix [
                                        0.0002449525 0.000329224 0.0003046354
                                        1.182355e-05 2.002576e-07 -1.143489e-08
                                      ]
                                    }
                                  }
                                }
                              ]
                              name "J4"
                              boundingObject USE j4
                              physics Physics {
                                density -1
                                mass 0.000826
                                centerOfMass [
                                  0.108899 0.008914 0.05615
                                ]
                                inertiaMatrix [
                                  2.656732e-08 2.710462e-08 4.124432e-08
                                  -1.065332e-19 2.78672e-24 2.3309e-24
                                ]
                              }
                            }
                          }
                        ]
                        name "J3"
                        boundingObject USE j3
                        physics Physics {
                          density -1
                          mass 2.394262
                          centerOfMass [
                            0.008237 0.00068 0.017646
                          ]
                          inertiaMatrix [
                            0.006334728 0.00732802 0.007260425
                            -4.950446e-05 -0.0007613547 -6.64726e-05
                          ]
                        }
                      }
                    }
                  ]
                  name "J2"
                  boundingObject USE j2
                  physics Physics {
                    density -1
                    mass 6.361362
                    centerOfMass [
                      -0.007993 -0.001801 0.121256
                    ]
                    inertiaMatrix [
                      0.1066513 0.08706777 0.03170156
                      8.068216e-05 0.001451138 -0.0005574152
                    ]
                  }
                }
              }
            ]
            name "J1"
            boundingObject USE j1
            physics Physics {
              density -1
              mass 14.354858
              centerOfMass [
                0.039191 -0.000668 0.318431
              ]
              inertiaMatrix [
                0.9059617 0.9590944 0.1326389
                -0.0006305855 -0.1324298 -0.0008315873
              ]
            }
          }
        }
      ]
      name "LRMate-200iD"
      boundingObject USE base
      physics Physics {
        density -1
        mass 4.853289
        centerOfMass [
          -0.006827 0.080423 0.000322
        ]
        inertiaMatrix [
          0.02198661 0.02280118 0.02382922
          0.0001430305 0.0001185041 3.060087e-05
        ]
      }
      controller "no RL"
      supervisor TRUE
    }
  ]
  controller "<none>"
  supervisor TRUE
}
Solid {
  translation -1.89208 0.310296 0.599773
  rotation -9.014980083973434e-12 -9.45202570290516e-12 1 -3.140892357128314
  children [
    DEF BOX_SHAPE Shape {
      appearance PBRAppearance {
        baseColorMap ImageTexture {
          url [
            "https://raw.githubusercontent.com/cyberbotics/webots/R2025a/projects/objects/factory/containers/protos/textures/wooden_box_base_color.jpg"
          ]
        }
        roughnessMap ImageTexture {
          url [
            "https://raw.githubusercontent.com/cyberbotics/webots/R2025a/projects/objects/factory/containers/protos/textures/wooden_box_roughness.jpg"
          ]
        }
        metalness 0
        normalMap ImageTexture {
          url [
            "https://raw.githubusercontent.com/cyberbotics/webots/R2025a/projects/objects/factory/containers/protos/textures/wooden_box_normal.jpg"
          ]
        }
        occlusionMap ImageTexture {
          url [
            "https://raw.githubusercontent.com/cyberbotics/webots/R2025a/projects/objects/factory/containers/protos/textures/wooden_box_occlusion.jpg"
          ]
        }
      }
      geometry Box {
        size 0.2 0.2 0.2
      }
    }
  ]
  name "wooden box"
  model "wooden box"
  boundingObject USE BOX_SHAPE
}
DEF grinder Solid {
  translation -0.91 0.185 0
  children [
    Solid {
      translation -5.143503540250283e-05 -1.8933227527717644e-06 -0.001483501809758675
      rotation 0.6546688548142531 -0.4315899191969425 -0.6205955463776476 1.7388959201076813e-05
      children [
        Solid {
          children [
            DEF BELT_TARGET Pose {
              translation 0.31 -0.185 0.64
              rotation 0.37796390461552926 -0.6546538347889604 0.6546538347889604 2.41886
            }
            Solid {
              children [
                Shape {
                  appearance PBRAppearance {
                    baseColor 0.529412 0.54902 0.54902
                  }
                  geometry DEF Grinder_Right Mesh {
                    url [
                      "../workpiece/Grinder_RightBelt.stl"
                    ]
                  }
                }
              ]
            }
            Shape {
              appearance PBRAppearance {
                baseColor 0.529412 0.54902 0.54902
              }
              geometry DEF Grinder_Left Mesh {
                url [
                  "../workpiece/Grinder_LeftBelt.stl"
                ]
              }
            }
          ]
        }
        Shape {
          appearance PBRAppearance {
            baseColor 0.976471 0.85098 0.14902
          }
          geometry DEF Grinder_Shell Mesh {
            url [
              "../workpiece/Grinder_Shell.stl"
            ]
          }
        }
      ]
    }
    Shape {
      appearance PBRAppearance {
        baseColor 0.976471 0.85098 0.14902
      }
      geometry DEF Grinder_Bottom Mesh {
        url [
          "../workpiece/Grinder_Bottom.stl"
        ]
      }
    }
  ]
  name "solid(1)"
  boundingObject USE Grinder_Bottom
}
DEF grinding_wheel Robot {
  translation -0.654 -0.002 0.613
  rotation 1 0 0 1.5708003061004252
  children [
    HingeJoint {
      jointParameters HingeJointParameters {
        axis 0 0 1
      }
      device [
        DEF wheel_motor RotationalMotor {
          name "wheel_motor"
          maxVelocity 30
        }
      ]
      endPoint DEF grinding_wheel Solid {
        children [
          Solid {
            translation 0.06 0 0
            children [
              Shape {
                geometry Sphere {
                  radius 0.01
                }
              }
            ]
          }
          DEF BELT_TARGET_2 Pose {
            translation 0.06 0 0
            rotation 0 1 0 1.5708003061004252
          }
          DEF wheel Shape {
            appearance PBRAppearance {
            }
            geometry Cylinder {
              height 0.04
              radius 0.06
            }
          }
        ]
      }
    }
  ]
  name "robot(1)"
  boundingObject USE wheel
  controller "grinding_wheel"
  supervisor TRUE
}
